
local _ = {name = "air", prob = 0}
local L = {name = "default:jungleleaves", prob = 255}
local N = {name = "default:jungleleaves", prob = 223}
local M = {name = "default:jungleleaves", prob = 191}
local B = {name = "default:jungletree", prob = 255, force_place = true}
local Y = {name = "default:jungletree", prob = 191, force_place = true}
local U = {name = "default:jungletree", prob = 127, force_place = true}
local I = {name = "default:jungletree", prob = 255}

do
local jungletree_data = {
	size = {x = 5, y = 17, z = 5},
	data = {
		_, _, _, _, _,
		_, _, _, _, _,
		_, _, _, _, _,
		_, _, _, _, _,
		_, _, _, _, _,
		_, _, _, _, _,
		_, _, _, _, _,
		_, _, _, _, _,
		_, _, _, _, _,
		_, _, _, _, _,
		N, L, N, _, _,
		_, _, N, L, N,
		_, _, _, _, _,
		_, _, _, _, _,
		M, N, N, N, M,
		M, N, N, N, M,
		_, _, _, _, _,

		_, _, B, _, _,
		_, _, B, _, _,
		_, _, U, _, _,
		_, _, _, _, _,
		_, _, _, _, _,
		_, _, _, _, _,
		_, _, _, _, _,
		_, _, _, _, _,
		_, _, _, _, _,
		_, _, _, _, _,
		L, B, L, _, _,
		_, _, L, B, L,
		_, _, _, _, _,
		_, _, _, _, _,
		N, B, L, B, N,
		N, L, L, L, N,
		_, N, N, N, _,

		_, B, B, B, _,
		_, B, B, B, _,
		_, U, B, U, _,
		_, _, B, _, _,
		_, _, B, _, _,
		_, _, B, _, _,
		_, _, B, _, _,
		_, _, B, _, _,
		_, _, B, L, N,
		N, L, B, _, _,
		N, L, B, _, _,
		_, _, B, L, N,
		_, _, B, L, N,
		_, _, B, _, _,
		N, L, L, L, N,
		N, L, L, L, N,
		_, N, L, N, _,

		_, _, B, _, _,
		_, _, B, _, _,
		_, _, U, _, _,
		_, _, _, _, _,
		_, _, _, _, _,
		_, _, _, _, _,
		_, _, _, _, _,
		_, _, _, _, _,
		_, _, L, B, L,
		L, B, L, _, _,
		_, _, _, _, _,
		_, _, _, _, _,
		_, _, L, B, L,
		_, _, _, _, _,
		N, B, L, B, N,
		N, L, L, L, N,
		_, N, N, N, _,

		_, _, _, _, _,
		_, _, _, _, _,
		_, _, _, _, _,
		_, _, _, _, _,
		_, _, _, _, _,
		_, _, _, _, _,
		_, _, _, _, _,
		_, _, _, _, _,
		_, _, N, L, N,
		N, L, N, _, _,
		_, _, _, _, _,
		_, _, _, _, _,
		_, _, N, L, N,
		_, _, _, _, _,
		M, N, N, N, M,
		M, N, N, N, M,
		_, _, _, _, _,
	},
	yslice_prob = {
		{ypos=6, prob=191},
		{ypos=7, prob=191},
		{ypos=8, prob=191},
		{ypos=9, prob=191},
		{ypos=10, prob=191},
	},
}

local data = minetest.serialize_schematic(jungletree_data, "mts", {})
local file = io.open(cw.worldpath .. "/cw_jungletree_base.mts", "w")
file:write(data)
file:close()
end

do
-- Main difference is the trunk base doesn't have extra nodes around it.
local jungletree_data = {
	size = {x = 5, y = 17, z = 5},
	data = {
		_, _, _, _, _,
		_, _, _, _, _,
		_, _, _, _, _,
		_, _, _, _, _,
		_, _, _, _, _,
		_, _, _, _, _,
		_, _, _, _, _,
		_, _, _, _, _,
		_, _, _, _, _,
		_, _, _, _, _,
		N, L, N, _, _,
		_, _, N, L, N,
		_, _, _, _, _,
		_, _, _, _, _,
		M, N, N, N, M,
		M, N, N, N, M,
		_, _, _, _, _,

		_, _, _, _, _,
		_, _, _, _, _,
		_, _, _, _, _,
		_, _, _, _, _,
		_, _, _, _, _,
		_, _, _, _, _,
		_, _, _, _, _,
		_, _, _, _, _,
		_, _, _, _, _,
		_, _, _, _, _,
		L, B, L, _, _,
		_, _, L, B, L,
		_, _, _, _, _,
		_, _, _, _, _,
		N, B, L, B, N,
		N, L, L, L, N,
		_, N, N, N, _,

		_, _, B, _, _,
		_, _, B, _, _,
		_, _, B, _, _,
		_, _, B, _, _,
		_, _, B, _, _,
		_, _, B, _, _,
		_, _, B, _, _,
		_, _, B, _, _,
		_, _, B, L, N,
		N, L, B, _, _,
		N, L, B, _, _,
		_, _, B, L, N,
		_, _, B, L, N,
		_, _, B, _, _,
		N, L, L, L, N,
		N, L, L, L, N,
		_, N, L, N, _,

		_, _, _, _, _,
		_, _, _, _, _,
		_, _, _, _, _,
		_, _, _, _, _,
		_, _, _, _, _,
		_, _, _, _, _,
		_, _, _, _, _,
		_, _, _, _, _,
		_, _, L, B, L,
		L, B, L, _, _,
		_, _, _, _, _,
		_, _, _, _, _,
		_, _, L, B, L,
		_, _, _, _, _,
		N, B, L, B, N,
		N, L, L, L, N,
		_, N, N, N, _,

		_, _, _, _, _,
		_, _, _, _, _,
		_, _, _, _, _,
		_, _, _, _, _,
		_, _, _, _, _,
		_, _, _, _, _,
		_, _, _, _, _,
		_, _, _, _, _,
		_, _, N, L, N,
		N, L, N, _, _,
		_, _, _, _, _,
		_, _, _, _, _,
		_, _, N, L, N,
		_, _, _, _, _,
		M, N, N, N, M,
		M, N, N, N, M,
		_, _, _, _, _,
	},
	yslice_prob = {
		{ypos=6, prob=191},
		{ypos=7, prob=191},
		{ypos=8, prob=191},
		{ypos=9, prob=191},
		{ypos=10, prob=191},
	},
}

local data = minetest.serialize_schematic(jungletree_data, "mts", {})
local file = io.open(cw.worldpath .. "/cw_jungletree_top.mts", "w")
file:write(data)
file:close()
end

do
-- Main difference is there's no trunk at all!
local jungletree_data = {
	size = {x = 5, y = 17, z = 5},
	data = {
		_, _, _, _, _,
		_, _, _, _, _,
		_, _, _, _, _,
		_, _, _, _, _,
		_, _, _, _, _,
		_, _, _, _, _,
		_, _, _, _, _,
		_, _, _, _, _,
		_, _, _, _, _,
		_, _, _, _, _,
		_, _, _, _, _,
		_, _, _, _, _,
		_, _, _, _, _,
		M, N, N, N, M,
		M, N, N, N, M,
		M, N, N, N, M,
		_, _, _, _, _,

		_, _, _, _, _,
		_, _, _, _, _,
		_, _, _, _, _,
		_, _, _, _, _,
		_, _, _, _, _,
		_, _, _, _, _,
		_, _, _, _, _,
		_, _, _, _, _,
		_, _, _, _, _,
		_, _, _, _, _,
		_, _, _, _, _,
		_, _, _, _, _,
		_, _, _, _, _,
		N, L, L, L, N,
		N, B, L, B, N,
		N, L, L, L, N,
		_, N, N, N, _,

		_, _, _, _, _,
		_, _, _, _, _,
		_, _, _, _, _,
		_, _, _, _, _,
		_, _, _, _, _,
		_, _, _, _, _,
		_, _, _, _, _,
		_, _, _, _, _,
		_, _, _, _, _,
		_, _, _, _, _,
		_, _, _, _, _,
		_, _, _, _, _,
		_, _, _, _, _,
		N, L, L, L, N,
		N, L, L, L, N,
		N, L, L, L, N,
		_, N, L, N, _,

		_, _, _, _, _,
		_, _, _, _, _,
		_, _, _, _, _,
		_, _, _, _, _,
		_, _, _, _, _,
		_, _, _, _, _,
		_, _, _, _, _,
		_, _, _, _, _,
		_, _, _, _, _,
		_, _, _, _, _,
		_, _, _, _, _,
		_, _, _, _, _,
		_, _, _, _, _,
		N, L, L, L, N,
		N, B, L, B, N,
		N, L, L, L, N,
		_, N, N, N, _,

		_, _, _, _, _,
		_, _, _, _, _,
		_, _, _, _, _,
		_, _, _, _, _,
		_, _, _, _, _,
		_, _, _, _, _,
		_, _, _, _, _,
		_, _, _, _, _,
		_, _, _, _, _,
		_, _, _, _, _,
		_, _, _, _, _,
		_, _, _, _, _,
		_, _, _, _, _,
		M, N, N, N, M,
		M, N, N, N, M,
		M, N, N, N, M,
		_, _, _, _, _,
	},
	yslice_prob = {
		{ypos=6, prob=191},
		{ypos=7, prob=191},
		{ypos=8, prob=191},
		{ypos=9, prob=191},
		{ypos=10, prob=191},
	},
}

local data = minetest.serialize_schematic(jungletree_data, "mts", {})
local file = io.open(cw.worldpath .. "/cw_jungletree_notrunk.mts", "w")
file:write(data)
file:close()
end
